<?xml version="1.0" encoding="utf-8"?>
<!-- This URDF was automatically created by SolidWorks to URDF Exporter! Originally created by Stephen Brawner (brawner@gmail.com) 
     Commit Version: 1.6.0-4-g7f85cfe  Build Version: 1.6.7995.38578
     For more information, please see http://wiki.ros.org/sw_urdf_exporter -->
<robot
  name="X-DOG-URDF-7">
  <link
    name="base">
    <inertial>
      <origin
        xyz="0 0 0"
        rpy="0 0 0" />
      <mass value="5.6056"/>
      <inertia ixx="0.02456" ixy="0" ixz="0" iyy="0.05518" iyz="0" izz="0.07016"/>
    </inertial>
    <visual>
      <origin
        xyz="0 0 0"
        rpy="0 0 0" />
      <geometry>
        <mesh
          filename="../meshes/base.STL" />
      </geometry>
      <material
        name="">
        <color
          rgba="1 1 1 1" />
      </material>
    </visual>
    <collision>
      <origin
        xyz="-0.03 0 0"
        rpy="0 0 0" />
      <geometry>
        <box size="0.3 0.1 0.1" />
      </geometry>
    </collision>
  </link>
  <link
    name="FL_hip">
    <inertial>
      <origin
        xyz="-0.016524 -0.018717 -1.028E-05"
        rpy="0 0 0" />
      <mass
        value="0.678" />
      <inertia
        ixx="9.3893E-05"
        ixy="-9.6966E-07"
        ixz="4.9869E-08"
        iyy="0.00013301"
        iyz="2.623E-08"
        izz="6.7241E-05" />
    </inertial>
    <visual>
      <origin
        xyz="0 0 0"
        rpy="0 0 0" />
      <geometry>
        <mesh
          filename="../meshes/FL_hip.STL" />
      </geometry>
      <material
        name="">
        <color
          rgba="0.79216 0.81961 0.93333 1" />
      </material>
    </visual>
    <collision>
      <origin
        xyz="0 0.07 0"
        rpy="1.5707963267948966 0 0" />
      <geometry>
        <cylinder length="0.05" radius="0.046" />
      </geometry>
    </collision>
  </link>
  <joint
    name="FL_hip_joint" type="revolute">
    <origin
      xyz="0.17184 0.066326 0.0044898"
      rpy="0 0 0" />
    <parent
      link="base" />
    <child
      link="FL_hip" />
    <axis
      xyz="1 0 0" />
    <limit
      lower="-1.0472"
      upper="1.0472"
      effort="23.7"
      velocity="30.1" />
  </joint>
  <link
    name="FL_thigh">
    <inertial>
      <origin
        xyz="-0.0049117 -0.0082491 -0.036087"
        rpy="0 0 0" />
      <mass
        value="1.152" />
      <inertia
        ixx="0.0016"
        ixy="1.083E-05"
        ixz="-0.00011423"
        iyy="0.0018537"
        iyz="6.5694E-05"
        izz="0.00031306" />
    </inertial>
    <visual>
      <origin
        xyz="0 0 0"
        rpy="0 0 0" />
      <geometry>
        <mesh
          filename="../meshes/FL_thigh.STL" />
      </geometry>
      <material
        name="">
        <color
          rgba="0.79216 0.81961 0.93333 1" />
      </material>
    </visual>
    <collision>
      <origin
        xyz="-0.01 0.028 -0.06"
        rpy="0 1.5707963267948966 0" />
      <geometry>
        <box size="0.213 0.0245 0.06" />
      </geometry>
    </collision>
  </link>
  <joint
    name="FL_thigh_joint" type="revolute">
    <origin
      xyz="0 0.0636 0"
      rpy="0 0 0" />
    <parent
      link="FL_hip" />
    <child
      link="FL_thigh" />
    <axis
      xyz="0 1 0" />
    <limit
      lower="-1.5708"
      upper="3.4907"
      effort="23.7"
      velocity="30.1" />
  </joint>
  <link
    name="FL_calf">
    <inertial>
      <origin
        xyz="0.010831 -8.9768E-09 -0.092101"
        rpy="0 0 0" />
      <mass
        value="0.154" />
      <inertia
        ixx="0.0001146"
        ixy="-8.0208E-11"
        ixz="1.6264E-05"
        iyy="0.00012418"
        iyz="-1.4152E-11"
        izz="1.2226E-05" />
    </inertial>
    <visual>
      <origin
        xyz="0 0 0"
        rpy="0 0 0" />
      <geometry>
        <mesh
          filename="../meshes/FL_calf.STL" />
      </geometry>
      <material
        name="">
        <color
          rgba="0.49804 0.49804 0.49804 1" />
      </material>
    </visual>
    <collision>
      <origin
        xyz="0.01 0 -0.05"
        rpy="0 -0.21 0" />
      <geometry>
        <cylinder length="0.15" radius="0.012" />
      </geometry>
    </collision>
  </link>
  <joint
    name="FL_calf_joint" type="revolute">
    <origin
      xyz="0 0.015602 -0.21314"
      rpy="0 0 0" />
    <parent
      link="FL_thigh" />
    <child
      link="FL_calf" />
    <axis
      xyz="0 1 0" />
    <limit
      lower="-2.7227"
      upper="0.01"
      effort="45.43"
      velocity="15.7" />
  </joint>
  <link
    name="FL_calflower">
    <collision>
      <origin
        xyz="0 -8.9944E-09 -0.02"
        rpy="0 0 2" />
      <geometry>
        <cylinder length="0.06" radius="0.011" />
      </geometry>
    </collision>
  </link>
  <joint
    name="FL_calflower_joint"  type="fixed" dont_collapse="true">
    <origin
      xyz="0.02013 0 -0.13686"
      rpy="0 0 0" />
    <parent
      link="FL_calf" />
    <child
      link="FL_calflower" />
    <axis
      xyz="0 0 0" />
  </joint>
  <link
    name="FL_foot">
    <inertial>
      <origin
        xyz="-0.0030465 -0.00024191 -0.0050819"
        rpy="0 0 0" />
      <mass
        value="0.04" />
      <inertia
        ixx="1.3663E-05"
        ixy="-7.7708E-08"
        ixz="1.5617E-07"
        iyy="1.5631E-05"
        iyz="-1.2891E-07"
        izz="1.3829E-05" />
    </inertial>
    <visual>
      <origin
        xyz="0 0 0"
        rpy="0 0 0" />
      <geometry>
        <mesh
          filename="../meshes/FL_foot.STL" />
      </geometry>
      <material
        name="">
        <color
          rgba="1 1 1 1" />
      </material>
    </visual>
    <collision>
      <origin
        xyz="-0.003 0 -0.005"
        rpy="0 0 0" />
      <geometry>
        <sphere radius="0.028" />
      </geometry>
    </collision>
  </link>
  <joint
    name="FL_foot_joint" type="fixed" dont_collapse="true">
    <origin
      xyz="0.002364 0 -0.1994" />
    <parent
      link="FL_calf" />
    <child
      link="FL_foot" />
    <axis
      xyz="0 0 0" />
  </joint>
  <link
    name="FR_hip">
    <inertial>
      <origin
        xyz="-0.016524 0.018717 -1.028E-05"
        rpy="0 0 0" />
      <mass
        value="0.678" />
      <inertia
        ixx="9.3893E-05"
        ixy="1.0056E-06"
        ixz="-4.9868E-08"
        iyy="0.00013301"
        iyz="-3.2614E-08"
        izz="6.7241E-05" />
    </inertial>
    <visual>
      <origin
        xyz="0 0 0"
        rpy="0 0 0" />
      <geometry>
        <mesh
          filename="../meshes/FR_hip.STL" />
      </geometry>
      <material
        name="">
        <color
          rgba="0.79216 0.81961 0.93333 1" />
      </material>
    </visual>
    <collision>
      <origin
        xyz="0 -0.07 0"
        rpy="1.5707963267948966 0 0" />
      <geometry>
        <cylinder length="0.05" radius="0.046" />
      </geometry>
    </collision>
  </link>
  <joint
    name="FR_hip_joint" type="revolute">
    <origin
      xyz="0.17184 -0.066326 0.0044898"
      rpy="0 0 0" />
    <parent
      link="base" />
    <child
      link="FR_hip" />
    <axis
      xyz="1 0 0" />
    <limit
      lower="-1.0472"
      upper="1.0472"
      effort="23.7"
      velocity="30.1" />
  </joint>
  <link
    name="FR_thigh">
    <inertial>
      <origin
        xyz="-0.0049117 0.0082491 -0.036087"
        rpy="0 0 0" />
      <mass
        value="1.152" />
      <inertia
        ixx="0.0016006"
        ixy="-1.0985E-05"
        ixz="-0.00011519"
        iyy="0.0018536"
        iyz="-6.5225E-05"
        izz="0.00031237" />
    </inertial>
    <visual>
      <origin
        xyz="0 0 0"
        rpy="0 0 0" />
      <geometry>
        <mesh
          filename="../meshes/FR_thigh.STL" />
      </geometry>
      <material
        name="">
        <color
          rgba="0.79216 0.81961 0.93333 1" />
      </material>
    </visual>
    <collision>
      <origin
        xyz="-0.01 -0.028 -0.06"
        rpy="0 1.5707963267948966 0" />
      <geometry>
        <box size="0.213 0.0245 0.06" />
      </geometry>
    </collision>
  </link>
  <joint
    name="FR_thigh_joint" type="revolute">
    <origin
      xyz="0 -0.0636 0"
      rpy="0 0 0" />
    <parent
      link="FR_hip" />
    <child
      link="FR_thigh" />
    <axis
      xyz="0 1 0" />
    <limit
      lower="-1.5708"
      upper="3.4907"
      effort="23.7"
      velocity="30.1" />
  </joint>
  <link
    name="FR_calf">
    <inertial>
      <origin
        xyz="0.010831 8.9768E-09 -0.092101"
        rpy="0 0 0" />
      <mass
        value="0.154" />
      <inertia
        ixx="0.0001146"
        ixy="-8.0206E-11"
        ixz="1.6265E-05"
        iyy="0.00012418"
        iyz="-1.4174E-11"
        izz="1.2226E-05" />
    </inertial>
    <visual>
      <origin
        xyz="0 0 0"
        rpy="0 0 0" />
      <geometry>
        <mesh
          filename="../meshes/FR_calf.STL" />
      </geometry>
      <material
        name="">
        <color
          rgba="0.49804 0.49804 0.49804 1" />
      </material>
    </visual>
    <collision>
      <origin
        xyz="0.01 0 -0.05"
        rpy="0 -0.21 0" />
      <geometry>
        <cylinder length="0.15" radius="0.012" />
      </geometry>
    </collision>
  </link>
  <joint
    name="FR_calf_joint" type="revolute">
    <origin
      xyz="0 -0.015602 -0.21314"
      rpy="0 0 0" />
    <parent
      link="FR_thigh" />
    <child
      link="FR_calf" />
    <axis
      xyz="0 1 0" />
    <limit
      lower="-2.7227"
      upper="0.01"
      effort="45.43"
      velocity="15.7" />
  </joint>
  <link
    name="FR_calflower">
    <collision>
      <origin
        xyz="0 -8.9944E-09 -0.02"
        rpy="0 0 2" />
      <geometry>
        <cylinder length="0.06" radius="0.011" />
      </geometry>
    </collision>
  </link>
  <joint
    name="FR_calflower_joint" type="fixed" dont_collapse="true">
    <origin
      xyz="0.02013 0 -0.13686"
      rpy="0 0 0" />
    <parent
      link="FR_calf" />
    <child
      link="FR_calflower" />
    <axis
      xyz="0 0 0" />
  </joint>
  <link
    name="FR_foot">
    <inertial>
      <origin
        xyz="-0.0030465 0.00024191 -0.0050819"
        rpy="0 0 0" />
      <mass
        value="0.04" />
      <inertia
        ixx="1.3663E-05"
        ixy="-7.7707E-08"
        ixz="1.5617E-07"
        iyy="1.5631E-05"
        iyz="-1.2891E-07"
        izz="1.3829E-05" />
    </inertial>
    <visual>
      <origin
        xyz="0 0 0"
        rpy="0 0 0" />
      <geometry>
        <mesh
          filename="../meshes/FR_foot.STL" />
      </geometry>
      <material
        name="">
        <color
          rgba="1 1 1 1" />
      </material>
    </visual>
    <collision>
      <origin
        xyz="-0.003 0 -0.005"
        rpy="0 0 0" />
      <geometry>
        <sphere radius="0.028" />
      </geometry>
    </collision>
  </link>
  <joint
    name="FR_foot_joint" type="fixed" dont_collapse="true">
    <origin
      xyz="0.002364 0 -0.1994"
       />
    <parent
      link="FR_calf" />
    <child
      link="FR_foot" />
    <axis
      xyz="0 0 0" />
  </joint>
  <link
    name="RL_hip">
    <inertial>
      <origin
        xyz="0.016553 -0.018717 -6.776E-06"
        rpy="0 0 0" />
      <mass
        value="0.678" />
      <inertia
        ixx="9.3893E-05"
        ixy="1.0056E-06"
        ixz="4.9869E-08"
        iyy="0.00013301"
        iyz="3.2613E-08"
        izz="6.7241E-05" />
    </inertial>
    <visual>
      <origin
        xyz="0 0 0"
        rpy="0 0 0" />
      <geometry>
        <mesh
          filename="../meshes/RL_hip.STL" />
      </geometry>
      <material
        name="">
        <color
          rgba="0.79216 0.81961 0.93333 1" />
      </material>
    </visual>
    <collision>
      <origin
        xyz="0 0.07 0"
        rpy="1.5707963267948966 0 0" />
      <geometry>
        <cylinder length="0.05" radius="0.046" />
      </geometry>
    </collision>
  </link>
  <joint
    name="RL_hip_joint" type="revolute">
    <origin
      xyz="-0.22336 0.066328 0.0044897"
      rpy="0 0 0" />
    <parent
      link="base" />
    <child
      link="RL_hip" />
    <axis
      xyz="1 0 0" />
    <limit
      lower="-1.0472"
      upper="1.0472"
      effort="23.7"
      velocity="30.1" />
  </joint>
  <link
    name="RL_thigh">
    <inertial>
      <origin
        xyz="-0.0049761 -0.0082491 -0.036055"
        rpy="0 0 0" />
      <mass
        value="1.152" />
      <inertia
        ixx="0.0016006"
        ixy="1.0361E-05"
        ixz="-0.00011511"
        iyy="0.0018537"
        iyz="6.5539E-05"
        izz="0.00031239" />
    </inertial>
    <visual>
      <origin
        xyz="0 0 0"
        rpy="0 0 0" />
      <geometry>
        <mesh
          filename="../meshes/RL_thigh.STL" />
      </geometry>
      <material
        name="">
        <color
          rgba="0.79216 0.81961 0.93333 1" />
      </material>
    </visual>
    <collision>
      <origin
        xyz="-0.01 0.028 -0.06"
        rpy="0 1.5707963267948966 0" />
      <geometry>
        <box size="0.213 0.0245 0.06" />
      </geometry>
    </collision>
  </link>
  <joint
    name="RL_thigh_joint" type="revolute">
    <origin
      xyz="0 0.0636 0"
      rpy="0 0 0" />
    <parent
      link="RL_hip" />
    <child
      link="RL_thigh" />
    <axis
      xyz="0 1 0" />
    <limit
      lower="-0.5236"
      upper="4.5379"
      effort="23.7"
      velocity="30.1" />
  </joint>
  <link
    name="RL_calf">
    <inertial>
      <origin
        xyz="0.010831 -8.9944E-09 -0.092101"
        rpy="0 0 0" />
      <mass
        value="0.154" />
      <inertia
        ixx="0.0001146"
        ixy="-8.0209E-11"
        ixz="1.6264E-05"
        iyy="0.00012418"
        iyz="-1.4136E-11"
        izz="1.2226E-05" />
    </inertial>
    <visual>
      <origin
        xyz="0 0 0"
        rpy="0 0 0" />
      <geometry>
        <mesh
          filename="../meshes/RL_calf.STL" />
      </geometry>
      <material
        name="">
        <color
          rgba="0.49804 0.49804 0.49804 1" />
      </material>
    </visual>
    <collision>
      <origin
        xyz="0.01 0 -0.05"
        rpy="0 -0.21 0" />
      <geometry>
        <cylinder length="0.15" radius="0.012" />
      </geometry>
    </collision>
  </link>
  <joint
    name="RL_calf_joint" type="revolute">
    <origin
      xyz="0 0.015602 -0.21314"
      rpy="0 0 0" />
    <parent
      link="RL_thigh" />
    <child
      link="RL_calf" />
    <axis
      xyz="0 1 0" />
    <limit
      lower="-2.7227"
      upper="0.01"
      effort="45.43"
      velocity="15.7" />
  </joint>
  <link
    name="RL_calflower">
    <collision>
      <origin
        xyz="0 -8.9944E-09 -0.02"
        rpy="0 0 2" />
      <geometry>
        <cylinder length="0.06" radius="0.011" />
      </geometry>
    </collision>
  </link>
  <joint
    name="RL_calflower_joint" type="fixed" dont_collapse="true">
    <origin
      xyz="0.01533 0 -0.13686"
      rpy="0 0 0" />
    <parent
      link="RL_calf" />
    <child
      link="RL_calflower" />
    <axis
      xyz="0 0 0" />
  </joint>
  <link
    name="RL_foot">
    <inertial>
      <origin
        xyz="-0.0030466 -0.00024191 -0.0050819"
        rpy="0 0 0" />
      <mass
        value="0.04" />
      <inertia
        ixx="1.3663E-05"
        ixy="-7.7708E-08"
        ixz="1.5617E-07"
        iyy="1.5631E-05"
        iyz="-1.2891E-07"
        izz="1.3829E-05" />
    </inertial>
    <visual>
      <origin
        xyz="0 0 0"
        rpy="0 0 0" />
      <geometry>
        <mesh
          filename="../meshes/RL_foot.STL" />
      </geometry>
      <material
        name="">
        <color
          rgba="1 1 1 1" />
      </material>
    </visual>
    <collision>
      <origin
        xyz="-0.003 0 -0.005"
        rpy="0 0 0" />
      <geometry>
        <sphere radius="0.028" />
      </geometry>
    </collision>
  </link>
  <joint
    name="RL_foot_joint" type="fixed" dont_collapse="true">
    <origin
      xyz="0.002364 0 -0.1994"
       />
    <parent
      link="RL_calf" />
    <child
      link="RL_foot" />
    <axis
      xyz="0 0 0" />
  </joint>
  <link
    name="RR_hip">
    <inertial>
      <origin
        xyz="0.016553 0.018717 -6.776E-06"
        rpy="0 0 0" />
      <mass
        value="0.678" />
      <inertia
        ixx="9.3893E-05"
        ixy="-9.6966E-07"
        ixz="-4.987E-08"
        iyy="0.00013301"
        iyz="-2.623E-08"
        izz="6.7241E-05" />
    </inertial>
    <visual>
      <origin
        xyz="0 0 0"
        rpy="0 0 0" />
      <geometry>
        <mesh
          filename="../meshes/RR_hip.STL" />
      </geometry>
      <material
        name="">
        <color
          rgba="0.79216 0.81961 0.93333 1" />
      </material>
    </visual>
    <collision>
      <origin
        xyz="0 -0.07 0"
        rpy="1.5707963267948966 0 0" />
      <geometry>
        <cylinder length="0.05" radius="0.046" />
      </geometry>
    </collision>
  </link>
  <joint
    name="RR_hip_joint" type="revolute">
    <origin
      xyz="-0.22336 -0.066328 0.0044897"
      rpy="0 0 0" />
    <parent
      link="base" />
    <child
      link="RR_hip" />
    <axis
      xyz="1 0 0" />
    <limit
      lower="-1.0472"
      upper="1.0472"
      effort="23.7"
      velocity="30.1" />
  </joint>
  <link
    name="RR_thigh">
    <inertial>
      <origin
        xyz="-0.0049761 0.0082491 -0.036055"
        rpy="0 0 0" />
      <mass
        value="1.152" />
      <inertia
        ixx="0.0016006"
        ixy="-1.0361E-05"
        ixz="-0.00011518"
        iyy="0.0018536"
        iyz="-6.5538E-05"
        izz="0.00031237" />
    </inertial>
    <visual>
      <origin
        xyz="0 0 0"
        rpy="0 0 0" />
      <geometry>
        <mesh
          filename="../meshes/RR_thigh.STL" />
      </geometry>
      <material
        name="">
        <color
          rgba="0.79216 0.81961 0.93333 1" />
      </material>
    </visual>
    <collision>
      <origin
        xyz="-0.01 -0.028 -0.06"
        rpy="0 1.5707963267948966 0" />
      <geometry>
        <box size="0.213 0.0245 0.06" />
      </geometry>
    </collision>
  </link>
  <joint
    name="RR_thigh_joint" type="revolute">
    <origin
      xyz="0 -0.0636 0"
      rpy="0 0 0" />
    <parent
      link="RR_hip" />
    <child
      link="RR_thigh" />
    <axis
      xyz="0 1 0" />
    <limit
      lower="-0.5236"
      upper="4.5379"
      effort="23.7"
      velocity="30.1" />
  </joint>
  <link
    name="RR_calf">
    <inertial>
      <origin
        xyz="0.010831 8.9944E-09 -0.092101"
        rpy="0 0 0" />
      <mass
        value="0.154" />
      <inertia
        ixx="0.0001146"
        ixy="-8.0208E-11"
        ixz="1.6265E-05"
        iyy="0.00012418"
        iyz="-1.4152E-11"
        izz="1.2226E-05" />
    </inertial>
    <visual>
      <origin
        xyz="0 0 0"
        rpy="0 0 0" />
      <geometry>
        <mesh
          filename="../meshes/RR_calf.STL" />
      </geometry>
      <material
        name="">
        <color
          rgba="0.49804 0.49804 0.49804 1" />
      </material>
    </visual>
    <collision>
      <origin
        xyz="0.01 0 -0.05"
        rpy="0 -0.21 0" />
      <geometry>
        <cylinder length="0.15" radius="0.012" />
      </geometry>
    </collision>
  </link>
  <joint
    name="RR_calf_joint" type="revolute">
    <origin
      xyz="0 -0.015602 -0.21314"
      rpy="0 0 0" />
    <parent
      link="RR_thigh" />
    <child
      link="RR_calf" />
    <axis
      xyz="0 1 0" />
    <limit
      lower="-2.7227"
      upper="0.01"
      effort="45.43"
      velocity="15.7" />
  </joint>
  <link
    name="RR_calflower">
    <collision>
      <origin
        xyz="0 -8.9944E-09 -0.02"
        rpy="0 0 2" />
      <geometry>
        <cylinder length="0.06" radius="0.011" />
      </geometry>
    </collision>
  </link>
  <joint
    name="RR_calflower_joint" type="fixed" dont_collapse="true">
    <origin
      xyz="0.01533 0 -0.13686"
      rpy="0 0 0" />
    <parent
      link="RR_calf" />
    <child
      link="RR_calflower" />
    <axis
      xyz="0 0 0" />
  </joint>
  <link
    name="RR_foot">
    <inertial>
      <origin
        xyz="-0.0030465 0.00024191 -0.0050819"
        rpy="0 0 0" />
      <mass
        value="0.04" />
      <inertia
        ixx="1.3663E-05"
        ixy="-7.7707E-08"
        ixz="1.5617E-07"
        iyy="1.5631E-05"
        iyz="-1.2891E-07"
        izz="1.3829E-05" />
    </inertial>
    <visual>
      <origin
        xyz="0 0 0"
        rpy="0 0 0" />
      <geometry>
        <mesh
          filename="../meshes/RR_foot.STL" />
      </geometry>
      <material
        name="">
        <color
          rgba="1 1 1 1" />
      </material>
    </visual>
    <collision>
      <origin
        xyz="-0.003 0 -0.005"
        rpy="0 0 0" />
      <geometry>
        <sphere radius="0.028" />
      </geometry>
    </collision>
  </link>
  <joint
    name="RR_foot_joint" type="fixed" dont_collapse="true">
    <origin
      xyz="0.002364 0 -0.1994"
       />
    <parent
      link="RR_calf" />
    <child
      link="RR_foot" />
    <axis
      xyz="0 0 0" />
  </joint>
  <joint name="imu_joint" type="fixed" dont_collapse="true">
    <origin xyz="-0.02557 0 0.04232" rpy="0 0 0" />
    <parent link="base" />
    <child link="imu" />
    <axis xyz="0 0 0" />
  </joint>
  <link name="imu">
    <inertial>
      <origin xyz="0 0 0" rpy="0 0 0" />
      <mass value="0" />
      <inertia ixx="0" ixy="0" ixz="0" iyy="0" iyz="0" izz="0" />
    </inertial>
  </link>
</robot>